/root/autodl-tmp/yao/rf_env/lib/python3.10/site-packages/lightning/pytorch/utilities/parsing.py:210: Attribute 'env' is an instance of `nn.Module` and is already saved during checkpointing. It is recommended to ignore them using `self.save_hyperparameters(ignore=['env'])`.
/root/autodl-tmp/yao/rf_env/lib/python3.10/site-packages/lightning/pytorch/utilities/parsing.py:210: Attribute 'policy' is an instance of `nn.Module` and is already saved during checkpointing. It is recommended to ignore them using `self.save_hyperparameters(ignore=['policy'])`.
No solution file found at data/cvrp/test/100_sol_pyvrp.npz
No solution file found at data/cvrp/test/50_sol_pyvrp.npz
No solution file found at data/cvrp/test/50_sol_pyvrp.npz
Traceback (most recent call last):
  File "/root/.pycharm_helpers/pydev/_pydevd_bundle/pydevd_resolver.py", line 213, in resolve
    return dict[key]
KeyError: 'bias3'

During handling of the above exception, another exception occurred:

Traceback (most recent call last):
  File "/root/.pycharm_helpers/pydev/_pydevd_bundle/pydevd_comm.py", line 1882, in do_it
    var_obj = pydevd_vars.getVariable(self.thread_id, self.frame_id, scope, attrs)
  File "/root/.pycharm_helpers/pydev/_pydevd_bundle/pydevd_vars.py", line 240, in getVariable
    var = resolver.resolve(var, k)
  File "/root/.pycharm_helpers/pydev/_pydevd_bundle/pydevd_resolver.py", line 215, in resolve
    return getattr(dict, key)
AttributeError: 'dict' object has no attribute 'bias3'

Traceback (most recent call last):
  File "/root/.pycharm_helpers/pydev/_pydevd_bundle/pydevd_resolver.py", line 213, in resolve
    return dict[key]
KeyError: 'current_node'

During handling of the above exception, another exception occurred:

Traceback (most recent call last):
  File "/root/.pycharm_helpers/pydev/_pydevd_bundle/pydevd_comm.py", line 1882, in do_it
    var_obj = pydevd_vars.getVariable(self.thread_id, self.frame_id, scope, attrs)
  File "/root/.pycharm_helpers/pydev/_pydevd_bundle/pydevd_vars.py", line 240, in getVariable
    var = resolver.resolve(var, k)
  File "/root/.pycharm_helpers/pydev/_pydevd_bundle/pydevd_resolver.py", line 215, in resolve
    return getattr(dict, key)
AttributeError: 'dict' object has no attribute 'current_node'

Traceback (most recent call last):
  File "/root/.pycharm_helpers/pydev/_pydevd_bundle/pydevd_resolver.py", line 213, in resolve
    return dict[key]
KeyError: 'glimpse_q'

During handling of the above exception, another exception occurred:

Traceback (most recent call last):
  File "/root/.pycharm_helpers/pydev/_pydevd_bundle/pydevd_comm.py", line 1882, in do_it
    var_obj = pydevd_vars.getVariable(self.thread_id, self.frame_id, scope, attrs)
  File "/root/.pycharm_helpers/pydev/_pydevd_bundle/pydevd_vars.py", line 240, in getVariable
    var = resolver.resolve(var, k)
  File "/root/.pycharm_helpers/pydev/_pydevd_bundle/pydevd_resolver.py", line 215, in resolve
    return getattr(dict, key)
AttributeError: 'dict' object has no attribute 'glimpse_q'

Traceback (most recent call last):
  File "/root/.pycharm_helpers/pydev/_pydevd_bundle/pydevd_resolver.py", line 213, in resolve
    return dict[key]
KeyError: 'glimpse_v'

During handling of the above exception, another exception occurred:

Traceback (most recent call last):
  File "/root/.pycharm_helpers/pydev/_pydevd_bundle/pydevd_comm.py", line 1882, in do_it
    var_obj = pydevd_vars.getVariable(self.thread_id, self.frame_id, scope, attrs)
  File "/root/.pycharm_helpers/pydev/_pydevd_bundle/pydevd_vars.py", line 240, in getVariable
    var = resolver.resolve(var, k)
  File "/root/.pycharm_helpers/pydev/_pydevd_bundle/pydevd_resolver.py", line 215, in resolve
    return getattr(dict, key)
AttributeError: 'dict' object has no attribute 'glimpse_v'

Traceback (most recent call last):
  File "/root/.pycharm_helpers/pydev/_pydevd_bundle/pydevd_resolver.py", line 213, in resolve
    return dict[key]
KeyError: 'logit_k'

During handling of the above exception, another exception occurred:

Traceback (most recent call last):
  File "/root/.pycharm_helpers/pydev/_pydevd_bundle/pydevd_comm.py", line 1882, in do_it
    var_obj = pydevd_vars.getVariable(self.thread_id, self.frame_id, scope, attrs)
  File "/root/.pycharm_helpers/pydev/_pydevd_bundle/pydevd_vars.py", line 240, in getVariable
    var = resolver.resolve(var, k)
  File "/root/.pycharm_helpers/pydev/_pydevd_bundle/pydevd_resolver.py", line 215, in resolve
    return getattr(dict, key)
AttributeError: 'dict' object has no attribute 'logit_k'

Traceback (most recent call last):
  File "/root/.pycharm_helpers/pydev/_pydevd_bundle/pydevd_resolver.py", line 213, in resolve
    return dict[key]
KeyError: 'glimpse_k'

During handling of the above exception, another exception occurred:

Traceback (most recent call last):
  File "/root/.pycharm_helpers/pydev/_pydevd_bundle/pydevd_comm.py", line 1882, in do_it
    var_obj = pydevd_vars.getVariable(self.thread_id, self.frame_id, scope, attrs)
  File "/root/.pycharm_helpers/pydev/_pydevd_bundle/pydevd_vars.py", line 240, in getVariable
    var = resolver.resolve(var, k)
  File "/root/.pycharm_helpers/pydev/_pydevd_bundle/pydevd_resolver.py", line 215, in resolve
    return getattr(dict, key)
AttributeError: 'dict' object has no attribute 'glimpse_k'

Traceback (most recent call last):
  File "/root/.pycharm_helpers/pydev/_pydevd_bundle/pydevd_resolver.py", line 213, in resolve
    return dict[key]
KeyError: 'mask'

During handling of the above exception, another exception occurred:

Traceback (most recent call last):
  File "/root/.pycharm_helpers/pydev/_pydevd_bundle/pydevd_comm.py", line 1882, in do_it
    var_obj = pydevd_vars.getVariable(self.thread_id, self.frame_id, scope, attrs)
  File "/root/.pycharm_helpers/pydev/_pydevd_bundle/pydevd_vars.py", line 240, in getVariable
    var = resolver.resolve(var, k)
  File "/root/.pycharm_helpers/pydev/_pydevd_bundle/pydevd_resolver.py", line 215, in resolve
    return getattr(dict, key)
AttributeError: 'dict' object has no attribute 'mask'

Traceback (most recent call last):
  File "/root/.pycharm_helpers/pydev/_pydevd_bundle/pydevd_resolver.py", line 213, in resolve
    return dict[key]
KeyError: 'logits'

During handling of the above exception, another exception occurred:

Traceback (most recent call last):
  File "/root/.pycharm_helpers/pydev/_pydevd_bundle/pydevd_comm.py", line 1882, in do_it
    var_obj = pydevd_vars.getVariable(self.thread_id, self.frame_id, scope, attrs)
  File "/root/.pycharm_helpers/pydev/_pydevd_bundle/pydevd_vars.py", line 240, in getVariable
    var = resolver.resolve(var, k)
  File "/root/.pycharm_helpers/pydev/_pydevd_bundle/pydevd_resolver.py", line 215, in resolve
    return getattr(dict, key)
AttributeError: 'dict' object has no attribute 'logits'

Traceback (most recent call last):
  File "/root/.pycharm_helpers/pydev/_pydevd_bundle/pydevd_resolver.py", line 213, in resolve
    return dict[key]
KeyError: 'glimpse_k'

During handling of the above exception, another exception occurred:

Traceback (most recent call last):
  File "/root/.pycharm_helpers/pydev/_pydevd_bundle/pydevd_comm.py", line 1882, in do_it
    var_obj = pydevd_vars.getVariable(self.thread_id, self.frame_id, scope, attrs)
  File "/root/.pycharm_helpers/pydev/_pydevd_bundle/pydevd_vars.py", line 240, in getVariable
    var = resolver.resolve(var, k)
  File "/root/.pycharm_helpers/pydev/_pydevd_bundle/pydevd_resolver.py", line 215, in resolve
    return getattr(dict, key)
AttributeError: 'dict' object has no attribute 'glimpse_k'

Traceback (most recent call last):
  File "/root/.pycharm_helpers/pydev/_pydevd_bundle/pydevd_resolver.py", line 213, in resolve
    return dict[key]
KeyError: 'current_node'

During handling of the above exception, another exception occurred:

Traceback (most recent call last):
  File "/root/.pycharm_helpers/pydev/_pydevd_bundle/pydevd_comm.py", line 1882, in do_it
    var_obj = pydevd_vars.getVariable(self.thread_id, self.frame_id, scope, attrs)
  File "/root/.pycharm_helpers/pydev/_pydevd_bundle/pydevd_vars.py", line 240, in getVariable
    var = resolver.resolve(var, k)
  File "/root/.pycharm_helpers/pydev/_pydevd_bundle/pydevd_resolver.py", line 215, in resolve
    return getattr(dict, key)
AttributeError: 'dict' object has no attribute 'current_node'

Traceback (most recent call last):
  File "/root/.pycharm_helpers/pydev/_pydevd_bundle/pydevd_resolver.py", line 213, in resolve
    return dict[key]
KeyError: 'bias3'

During handling of the above exception, another exception occurred:

Traceback (most recent call last):
  File "/root/.pycharm_helpers/pydev/_pydevd_bundle/pydevd_comm.py", line 1882, in do_it
    var_obj = pydevd_vars.getVariable(self.thread_id, self.frame_id, scope, attrs)
  File "/root/.pycharm_helpers/pydev/_pydevd_bundle/pydevd_vars.py", line 240, in getVariable
    var = resolver.resolve(var, k)
  File "/root/.pycharm_helpers/pydev/_pydevd_bundle/pydevd_resolver.py", line 215, in resolve
    return getattr(dict, key)
AttributeError: 'dict' object has no attribute 'bias3'

Traceback (most recent call last):
  File "/root/.pycharm_helpers/pydev/_pydevd_bundle/pydevd_resolver.py", line 213, in resolve
    return dict[key]
KeyError: 'mask'

During handling of the above exception, another exception occurred:

Traceback (most recent call last):
  File "/root/.pycharm_helpers/pydev/_pydevd_bundle/pydevd_comm.py", line 1882, in do_it
    var_obj = pydevd_vars.getVariable(self.thread_id, self.frame_id, scope, attrs)
  File "/root/.pycharm_helpers/pydev/_pydevd_bundle/pydevd_vars.py", line 240, in getVariable
    var = resolver.resolve(var, k)
  File "/root/.pycharm_helpers/pydev/_pydevd_bundle/pydevd_resolver.py", line 215, in resolve
    return getattr(dict, key)
AttributeError: 'dict' object has no attribute 'mask'

Traceback (most recent call last):
  File "/root/.pycharm_helpers/pydev/_pydevd_bundle/pydevd_resolver.py", line 213, in resolve
    return dict[key]
KeyError: 'logit_k'

During handling of the above exception, another exception occurred:

Traceback (most recent call last):
  File "/root/.pycharm_helpers/pydev/_pydevd_bundle/pydevd_comm.py", line 1882, in do_it
    var_obj = pydevd_vars.getVariable(self.thread_id, self.frame_id, scope, attrs)
  File "/root/.pycharm_helpers/pydev/_pydevd_bundle/pydevd_vars.py", line 240, in getVariable
    var = resolver.resolve(var, k)
  File "/root/.pycharm_helpers/pydev/_pydevd_bundle/pydevd_resolver.py", line 215, in resolve
    return getattr(dict, key)
AttributeError: 'dict' object has no attribute 'logit_k'

Traceback (most recent call last):
  File "/root/.pycharm_helpers/pydev/_pydevd_bundle/pydevd_resolver.py", line 213, in resolve
    return dict[key]
KeyError: 'glimpse_v'

During handling of the above exception, another exception occurred:

Traceback (most recent call last):
  File "/root/.pycharm_helpers/pydev/_pydevd_bundle/pydevd_comm.py", line 1882, in do_it
    var_obj = pydevd_vars.getVariable(self.thread_id, self.frame_id, scope, attrs)
  File "/root/.pycharm_helpers/pydev/_pydevd_bundle/pydevd_vars.py", line 240, in getVariable
    var = resolver.resolve(var, k)
  File "/root/.pycharm_helpers/pydev/_pydevd_bundle/pydevd_resolver.py", line 215, in resolve
    return getattr(dict, key)
AttributeError: 'dict' object has no attribute 'glimpse_v'

Traceback (most recent call last):
  File "/root/.pycharm_helpers/pydev/_pydevd_bundle/pydevd_resolver.py", line 213, in resolve
    return dict[key]
KeyError: 'glimpse_q'

During handling of the above exception, another exception occurred:

Traceback (most recent call last):
  File "/root/.pycharm_helpers/pydev/_pydevd_bundle/pydevd_comm.py", line 1882, in do_it
    var_obj = pydevd_vars.getVariable(self.thread_id, self.frame_id, scope, attrs)
  File "/root/.pycharm_helpers/pydev/_pydevd_bundle/pydevd_vars.py", line 240, in getVariable
    var = resolver.resolve(var, k)
  File "/root/.pycharm_helpers/pydev/_pydevd_bundle/pydevd_resolver.py", line 215, in resolve
    return getattr(dict, key)
AttributeError: 'dict' object has no attribute 'glimpse_q'

Traceback (most recent call last):
  File "/root/.pycharm_helpers/pydev/_pydevd_bundle/pydevd_resolver.py", line 213, in resolve
    return dict[key]
KeyError: 'logits'

During handling of the above exception, another exception occurred:

Traceback (most recent call last):
  File "/root/.pycharm_helpers/pydev/_pydevd_bundle/pydevd_comm.py", line 1882, in do_it
    var_obj = pydevd_vars.getVariable(self.thread_id, self.frame_id, scope, attrs)
  File "/root/.pycharm_helpers/pydev/_pydevd_bundle/pydevd_vars.py", line 240, in getVariable
    var = resolver.resolve(var, k)
  File "/root/.pycharm_helpers/pydev/_pydevd_bundle/pydevd_resolver.py", line 215, in resolve
    return getattr(dict, key)
AttributeError: 'dict' object has no attribute 'logits'

Traceback (most recent call last):
  File "/root/.pycharm_helpers/pydev/_pydevd_bundle/pydevd_resolver.py", line 213, in resolve
    return dict[key]
KeyError: 'bias3'

During handling of the above exception, another exception occurred:

Traceback (most recent call last):
  File "/root/.pycharm_helpers/pydev/_pydevd_bundle/pydevd_comm.py", line 1882, in do_it
    var_obj = pydevd_vars.getVariable(self.thread_id, self.frame_id, scope, attrs)
  File "/root/.pycharm_helpers/pydev/_pydevd_bundle/pydevd_vars.py", line 240, in getVariable
    var = resolver.resolve(var, k)
  File "/root/.pycharm_helpers/pydev/_pydevd_bundle/pydevd_resolver.py", line 215, in resolve
    return getattr(dict, key)
AttributeError: 'dict' object has no attribute 'bias3'

Traceback (most recent call last):
  File "/root/.pycharm_helpers/pydev/_pydevd_bundle/pydevd_resolver.py", line 213, in resolve
    return dict[key]
KeyError: 'glimpse_k'

During handling of the above exception, another exception occurred:

Traceback (most recent call last):
  File "/root/.pycharm_helpers/pydev/_pydevd_bundle/pydevd_comm.py", line 1882, in do_it
    var_obj = pydevd_vars.getVariable(self.thread_id, self.frame_id, scope, attrs)
  File "/root/.pycharm_helpers/pydev/_pydevd_bundle/pydevd_vars.py", line 240, in getVariable
    var = resolver.resolve(var, k)
  File "/root/.pycharm_helpers/pydev/_pydevd_bundle/pydevd_resolver.py", line 215, in resolve
    return getattr(dict, key)
AttributeError: 'dict' object has no attribute 'glimpse_k'

Traceback (most recent call last):
  File "/root/.pycharm_helpers/pydev/_pydevd_bundle/pydevd_resolver.py", line 213, in resolve
    return dict[key]
KeyError: 'current_node'

During handling of the above exception, another exception occurred:

Traceback (most recent call last):
  File "/root/.pycharm_helpers/pydev/_pydevd_bundle/pydevd_comm.py", line 1882, in do_it
    var_obj = pydevd_vars.getVariable(self.thread_id, self.frame_id, scope, attrs)
  File "/root/.pycharm_helpers/pydev/_pydevd_bundle/pydevd_vars.py", line 240, in getVariable
    var = resolver.resolve(var, k)
  File "/root/.pycharm_helpers/pydev/_pydevd_bundle/pydevd_resolver.py", line 215, in resolve
    return getattr(dict, key)
AttributeError: 'dict' object has no attribute 'current_node'

Traceback (most recent call last):
  File "/root/.pycharm_helpers/pydev/_pydevd_bundle/pydevd_resolver.py", line 213, in resolve
    return dict[key]
KeyError: 'mask'

During handling of the above exception, another exception occurred:

Traceback (most recent call last):
  File "/root/.pycharm_helpers/pydev/_pydevd_bundle/pydevd_comm.py", line 1882, in do_it
    var_obj = pydevd_vars.getVariable(self.thread_id, self.frame_id, scope, attrs)
  File "/root/.pycharm_helpers/pydev/_pydevd_bundle/pydevd_vars.py", line 240, in getVariable
    var = resolver.resolve(var, k)
  File "/root/.pycharm_helpers/pydev/_pydevd_bundle/pydevd_resolver.py", line 215, in resolve
    return getattr(dict, key)
AttributeError: 'dict' object has no attribute 'mask'

Traceback (most recent call last):
  File "/root/.pycharm_helpers/pydev/_pydevd_bundle/pydevd_resolver.py", line 213, in resolve
    return dict[key]
KeyError: 'logit_k'

During handling of the above exception, another exception occurred:

Traceback (most recent call last):
  File "/root/.pycharm_helpers/pydev/_pydevd_bundle/pydevd_comm.py", line 1882, in do_it
    var_obj = pydevd_vars.getVariable(self.thread_id, self.frame_id, scope, attrs)
  File "/root/.pycharm_helpers/pydev/_pydevd_bundle/pydevd_vars.py", line 240, in getVariable
    var = resolver.resolve(var, k)
  File "/root/.pycharm_helpers/pydev/_pydevd_bundle/pydevd_resolver.py", line 215, in resolve
    return getattr(dict, key)
AttributeError: 'dict' object has no attribute 'logit_k'

Traceback (most recent call last):
  File "/root/.pycharm_helpers/pydev/_pydevd_bundle/pydevd_resolver.py", line 213, in resolve
    return dict[key]
KeyError: 'logits'

During handling of the above exception, another exception occurred:

Traceback (most recent call last):
  File "/root/.pycharm_helpers/pydev/_pydevd_bundle/pydevd_comm.py", line 1882, in do_it
    var_obj = pydevd_vars.getVariable(self.thread_id, self.frame_id, scope, attrs)
  File "/root/.pycharm_helpers/pydev/_pydevd_bundle/pydevd_vars.py", line 240, in getVariable
    var = resolver.resolve(var, k)
  File "/root/.pycharm_helpers/pydev/_pydevd_bundle/pydevd_resolver.py", line 215, in resolve
    return getattr(dict, key)
AttributeError: 'dict' object has no attribute 'logits'

Traceback (most recent call last):
  File "/root/.pycharm_helpers/pydev/_pydevd_bundle/pydevd_resolver.py", line 213, in resolve
    return dict[key]
KeyError: 'glimpse_v'

During handling of the above exception, another exception occurred:

Traceback (most recent call last):
  File "/root/.pycharm_helpers/pydev/_pydevd_bundle/pydevd_comm.py", line 1882, in do_it
    var_obj = pydevd_vars.getVariable(self.thread_id, self.frame_id, scope, attrs)
  File "/root/.pycharm_helpers/pydev/_pydevd_bundle/pydevd_vars.py", line 240, in getVariable
    var = resolver.resolve(var, k)
  File "/root/.pycharm_helpers/pydev/_pydevd_bundle/pydevd_resolver.py", line 215, in resolve
    return getattr(dict, key)
AttributeError: 'dict' object has no attribute 'glimpse_v'

Traceback (most recent call last):
  File "/root/.pycharm_helpers/pydev/_pydevd_bundle/pydevd_resolver.py", line 213, in resolve
    return dict[key]
KeyError: 'glimpse_q'

During handling of the above exception, another exception occurred:

Traceback (most recent call last):
  File "/root/.pycharm_helpers/pydev/_pydevd_bundle/pydevd_comm.py", line 1882, in do_it
    var_obj = pydevd_vars.getVariable(self.thread_id, self.frame_id, scope, attrs)
  File "/root/.pycharm_helpers/pydev/_pydevd_bundle/pydevd_vars.py", line 240, in getVariable
    var = resolver.resolve(var, k)
  File "/root/.pycharm_helpers/pydev/_pydevd_bundle/pydevd_resolver.py", line 215, in resolve
    return getattr(dict, key)
AttributeError: 'dict' object has no attribute 'glimpse_q'

Traceback (most recent call last):
  File "/root/autodl-tmp/yao/Hercules/problems/mt_routefinder_unified/eval.py", line 186, in <module>
    main()
  File "/root/autodl-tmp/yao/Hercules/problems/mt_routefinder_unified/eval.py", line 169, in main
    o = test(policy, td_batch, env, device=device)
  File "/root/autodl-tmp/yao/rf_env/lib/python3.10/site-packages/torch/utils/_contextlib.py", line 120, in decorate_context
    return func(*args, **kwargs)
  File "/root/autodl-tmp/yao/Hercules/problems/mt_routefinder_unified/eval.py", line 63, in test
    out = policy(td, env, phase="test", num_starts=n_start, return_actions=True)
  File "/root/autodl-tmp/yao/rf_env/lib/python3.10/site-packages/torch/nn/modules/module.py", line 1773, in _wrapped_call_impl
    return self._call_impl(*args, **kwargs)
  File "/root/autodl-tmp/yao/rf_env/lib/python3.10/site-packages/torch/nn/modules/module.py", line 1784, in _call_impl
    return forward_call(*args, **kwargs)
  File "/root/autodl-tmp/yao/rf_env/lib/python3.10/site-packages/rl4co/models/common/constructive/base.py", line 230, in forward
    logits, mask = self.decoder(td, hidden, num_starts)
  File "/root/autodl-tmp/yao/rf_env/lib/python3.10/site-packages/torch/nn/modules/module.py", line 1773, in _wrapped_call_impl
    return self._call_impl(*args, **kwargs)
  File "/root/autodl-tmp/yao/rf_env/lib/python3.10/site-packages/torch/nn/modules/module.py", line 1784, in _call_impl
    return forward_call(*args, **kwargs)
  File "/root/autodl-tmp/yao/rf_env/lib/python3.10/site-packages/rl4co/models/zoo/am/decoder.py", line 302, in forward
    bias3 = self._compute_dynamic_bias(td) if ATTENTION_BIAS_decoder1 else None
  File "/root/autodl-tmp/yao/rf_env/lib/python3.10/site-packages/rl4co/models/zoo/am/decoder.py", line 204, in _compute_dynamic_bias
    cur_xy_flat = cur_xy.reshape(B * P, 1, 2)  # (B*P, 1, 2)
KeyboardInterrupt
